Workbook

Sheet ข้อมูลพนักงาน
A1: ลำดับ | B1: รหัสพนักงาน | C1: คำนำหน้า | D1: ชื่อ | E1: สกุล | F1: อัตราค่าแรง | G1: วันเดือนปีเกิด | H1: เริ่มทำงาน | I1: สถานะ
A2: 1 | C2: น.ส. | D2: ชิติมา | E2: กตัญญู | F2: 14900 | H2: 237956
A3: 2 | C3: นาง | D3: พรพิมล | E3: มั่นทอง | F3: 13500 | H3: 242463
A4: 3 | C4: น.ส. | D4: แสงงาม | E4: สะราคำ | F4: 20000 | H4: 234669
A5: 4 | C5: นาย | D5: กิตติศักดิ์ | E5: ศรีสำปทวน | F5: 358 | H5: 235272
A6: 5 | C6: นาย | D6: เกรียงไกร | E6: พึ่งพวก | F6: 420 | H6: 243871
A7: 6 | C7: นาย | D7: คมสัน | E7: บุญมา | F7: 348 | H7: 243740
A8: 7 | C8: น.ส. | D8: จารุวรรณ | E8: เปี่ยมเสน | F8: 348 | H8: 238512
A9: 8 | C9: น.ส. | D9: จิราภรณ์ | E9: สิงห์บุตร | F9: 350 | H9: 240984
A10: 9 | C10: นาย | D10: ชยันต์ | E10: บุญจันทร์ | F10: 348 | H10: 242303
A11: 10 | C11: นาง | D11: ชุติมา | E11: นวลศรีไพร | F11: 437 | H11: 235354
A12: 11 | C12: นาย | D12: ชูชาติ | E12: ไหมทอง | F12: 545 | H12: 235093
A13: 12 | C13: นาย | D13: ณรงค์ | E13: เปี่ยมสิน | F13: 418 | H13: 241571
A14: 13 | C14: นาย | D14: ณวัศพงษ์ | E14: สิทธิวิโรฒโภคิน | F14: 363 | H14: 243257
A15: 14 | C15: นาย | D15: ณัฐวุฒิ | E15: กุลแจ | F15: 351 | H15: 240598
A16: 15 | C16: นาย | D16: ดนัย | E16: ทองชื่น | F16: 348 | H16: 243651
A17: 16 | C17: นาย | D17: ติ่ง | E17: นาคสังข์ | F17: 503 | H17: 234856
A18: 17 | C18: นาย | D18: ทิม | E18: บุญมาทัน | F18: 348 | H18: 237008
A19: 18 | C19: นาย | D19: ธงชัย | E19: โพธิ์หิรัญ | F19: 388 | H19: 233710
A20: 19 | C20: นาย | D20: ธนงค์พร | E20: อ่อนคำ | F20: 348 | H20: 238512
A21: 20 | C21: นาย | D21: นิรุต | E21: นาคสังข์ | F21: 363 | H21: 236410
A22: 21 | C22: นาย | D22: บัดกรี | E22: แถวอุทุม | F22: 567 | H22: 234889
A23: 22 | C23: นาย | D23: บุญเลิศ | E23: อินสุข | F23: 358 | H23: 239930
A24: 23 | C24: นาย | D24: บุญส่ง | E24: ดวงเหม | F24: 358 | H24: 240455
A25: 24 | C25: นาย | D25: ประชา | E25: วรวงษ์ | F25: 348 | H25: 235928
A26: 25 | C26: นาย | D26: พัชรวัฒน์ | E26: สิทธิวิโรฒโภคิน | F26: 633 | H26: 234792
A27: 26 | C27: นาย | D27: ไพฑูรย์ | E27: ป้องเรือ | F27: 447 | H27: 235765
A28: 27 | C28: นาย | D28: มนิต | E28: เปี่ยมศิลป์ | F28: 348 | H28: 238512
A29: 28 | C29: นาย | D29: วิทูรย์ | E29: ทองชื่น | F29: 380 | H29: 234209
A30: 29 | C30: นาย | D30: เวียง | E30: น้ำทิพย์ | F30: 363 | H30: 235737
A31: 30 | C31: นาย | D31: สมพงษ์ | E31: พึ่งแย้ม | F31: 483 | H31: 234830
A32: 31 | C32: นาย | D32: สมพงษ์ | E32: สิงห์พันธ์ม่วง | F32: 348 | H32: 235802
A33: 32 | C33: นาย | D33: สังวาลย์ | E33: เพ็งผล | F33: 348 | H33: 238420
A34: 33 | C34: นาย | D34: สาธิต | E34: คล้ายสอน | F34: 439 | H34: 236534
A35: 34 | C35: นาย | D35: สำเนา | E35: เอี่ยมสะอาด | F35: 362 | H35: 240422
A36: 35 | C36: นาย | D36: สำราญ | E36: เข็มเงิน | F36: 647 | H36: 235363
A37: 36 | C37: นาย | D37: สุชัย | E37: ใจเย็น | F37: 348 | H37: 239977
A38: 37 | C38: นาย | D38: สุทน | E38: ธัญญเจริญ | F38: 358 | H38: 236619
A39: 38 | C39: นาง | D39: สุนีย์ | E39: นาคสังข์ | F39: 348 | H39: 236264
A40: 39 | C40: นาย | D40: สุวิชา | E40: จ้อยชู | F40: 358 | H40: 239930
...

Sheet ผลประโยช์นพนักงาน
A1: บริษัท ช. ไพศาล จำกัด
A2: การคำนวณผลประโยชน์ของพนักงาน | G2: Date | H2: 243983 | J2: Salary increase | K2: 0.03 | M2: อายุเกษียณ | N2: 60
A3: กรอกข้อมูล | I3: เป็นสูตร Excel ไม่ต้องกรอก
A4: ลำดับ | B4: รหัสพนักงาน | C4: คำนำหน้า | D4: ชื่อ | E4: นามสกุล | F4: วันเดือนปีเกิด | G4: วันที่เริ่มทำงาน | H4: เงินเดือน ณ สิ้นปีปัจจุบัน | I4: วันที่เกษียณ (อายุครบ 60) | J4: อายุปัจจุบัน | K4: อายุงานถึงปีเกษียณ | L4: อายุงานถึงปีปัจจุบัน | M4: อายุงานคงเหลือ | N4: เงินเดือน ณ วันเกษียณ | O4: ผลประโยชน์ของพนักงานที่ต้องจ่าย ณ วันเกษียณ | P4: ความน่าจะเป็นในการอยู่จนถึงวันเกษียณ | Q4: ประมาณการหนี้สินผลประโยชน์พนักงานที่คาดว่าจะต้องจ่าย ณ วันเกษียณ | R4: ผลประโยชน์ของพนักงานที่คาดว่าต้องจ่าย ณ วันสิ้นปีปัจจุบัน | S4: ยอดยกมา | T4: ต้นทุน | U4: คชจ.บริหาร | V4: คชจ.ขาย | W4: ลาออก | X4: อายุงาน (ปี/เดือน) | Y4: อายุ (ปี/เดือน)
A5: 1 | C5: นาง | D5: สวอง | E5: วายุพัฒน์ | F5: 213094 | G5: 231778 | H5: 11070 | I5: =DATE(YEAR(F5)+$N$2,MONTH(F5),DAY(F5)) -> 235008 | J5: =DATEDIF(F5,$H$2,"Y") -> 84 | K5: =DATEDIF(G5,I5,"Y") -> 8 | L5: =DATEDIF(G5,$H$2,"Y") -> 33 | M5: =IF($N$2-J5<=0,0,($N$2-J5)) -> 0 | N5: =ROUND(H5*(1+$K$2)^(M5),0) -> 11070 | O5: =N5*VLOOKUP($K5,[1]สูตร!$A$5:$D$10,4) -> 88560 | P5: =VLOOKUP(J5,[1]สูตร!$A$14:$D$19,4) -> 1 | Q5: =+O5*P5 -> 88560 | R5: =IF(J5>=$F$3,Q5,ROUND(Q5*L5/K5,2)) -> 88560
A6: 2 | C6: นางสาว | D6: จันทิพย์ | E6: แซ่โง้ว | F6: 215265 | G6: 232510 | H6: 0 | I6: =DATE(YEAR(F6)+$N$2,MONTH(F6),DAY(F6)) -> 237179 | J6: =DATEDIF(F6,$H$2,"Y") -> 78 | K6: =DATEDIF(G6,I6,"Y") -> 12 | L6: =DATEDIF(G6,$H$2,"Y") -> 31 | M6: =IF($N$2-J6<=0,0,($N$2-J6)) -> 0 | N6: =ROUND(H6*(1+$K$2)^(M6),0) -> 0 | O6: =N6*VLOOKUP($K6,[1]สูตร!$A$5:$D$10,4) -> 0 | P6: =VLOOKUP(J6,[1]สูตร!$A$14:$D$19,4) -> 1 | Q6: =+O6*P6 -> 0 | R6: =IF(J6>=$F$3,Q6,ROUND(Q6*L6/K6,2)) -> 0
A7: 3 | C7: นาง | D7: ประนอม | E7: สากุล | F7: 216332 | G7: 236802 | H7: 11160 | I7: =DATE(YEAR(F7)+$N$2,MONTH(F7),DAY(F7)) -> 238246 | J7: =DATEDIF(F7,$H$2,"Y") -> 75 | K7: =DATEDIF(G7,I7,"Y") -> 3 | L7: =DATEDIF(G7,$H$2,"Y") -> 19 | M7: =IF($N$2-J7<=0,0,($N$2-J7)) -> 0 | N7: =ROUND(H7*(1+$K$2)^(M7),0) -> 11160 | O7: =N7*VLOOKUP($K7,[1]สูตร!$A$5:$D$10,4) -> 66960 | P7: =VLOOKUP(J7,[1]สูตร!$A$14:$D$19,4) -> 1 | Q7: =+O7*P7 -> 66960 | R7: =IF(J7>=$F$3,Q7,ROUND(Q7*L7/K7,2)) -> 66960
A8: 4 | C8: นาย | D8: องอาจ | E8: สุวรรณฑา | F8: 216590 | G8: 235382 | H8: 0 | I8: =DATE(YEAR(F8)+$N$2,MONTH(F8),DAY(F8)) -> 238504 | J8: =DATEDIF(F8,$H$2,"Y") -> 75 | K8: =DATEDIF(G8,I8,"Y") -> 8 | L8: =DATEDIF(G8,$H$2,"Y") -> 23 | M8: =IF($N$2-J8<=0,0,($N$2-J8)) -> 0 | N8: =ROUND(H8*(1+$K$2)^(M8),0) -> 0 | O8: =N8*VLOOKUP($K8,[1]สูตร!$A$5:$D$10,4) -> 0 | P8: =VLOOKUP(J8,[1]สูตร!$A$14:$D$19,4) -> 1 | Q8: =+O8*P8 -> 0 | R8: =IF(J8>=$F$3,Q8,ROUND(Q8*L8/K8,2)) -> 0
A9: 5 | C9: นาย | D9: โชคชัย | E9: ปรีชาญาดีกุล | F9: 217270 | G9: 233027 | H9: 43600 | I9: =DATE(YEAR(F9)+$N$2,MONTH(F9),DAY(F9)) -> 239184 | J9: =DATEDIF(F9,$H$2,"Y") -> 73 | K9: =DATEDIF(G9,I9,"Y") -> 16 | L9: =DATEDIF(G9,$H$2,"Y") -> 29 | M9: =IF($N$2-J9<=0,0,($N$2-J9)) -> 0 | N9: =ROUND(H9*(1+$K$2)^(M9),0) -> 43600 | O9: =N9*VLOOKUP($K9,[1]สูตร!$A$5:$D$10,4) -> 436000 | P9: =VLOOKUP(J9,[1]สูตร!$A$14:$D$19,4) -> 1 | Q9: =+O9*P9 -> 436000 | R9: =IF(J9>=$F$3,Q9,ROUND(Q9*L9/K9,2)) -> 436000
A10: 6 | C10: นาย | D10: อำพร | E10: ชาติไธสง | F10: 217015 | G10: 233939 | H10: 29400 | I10: =DATE(YEAR(F10)+$N$2,MONTH(F10),DAY(F10)) -> 238929 | J10: =DATEDIF(F10,$H$2,"Y") -> 73 | K10: =DATEDIF(G10,I10,"Y") -> 13 | L10: =DATEDIF(G10,$H$2,"Y") -> 27 | M10: =IF($N$2-J10<=0,0,($N$2-J10)) -> 0 | N10: =ROUND(H10*(1+$K$2)^(M10),0) -> 29400 | O10: =N10*VLOOKUP($K10,[1]สูตร!$A$5:$D$10,4) -> 294000 | P10: =VLOOKUP(J10,[1]สูตร!$A$14:$D$19,4) -> 1 | Q10: =+O10*P10 -> 294000 | R10: =IF(J10>=$F$3,Q10,ROUND(Q10*L10/K10,2)) -> 294000
A11: 7 | C11: นางสาว | D11: นาง | E11: ดีสุวรรณ | F11: 217753 | G11: 231778 | H11: 11100 | I11: =DATE(YEAR(F11)+$N$2,MONTH(F11),DAY(F11)) -> 239667 | J11: =DATEDIF(F11,$H$2,"Y") -> 71 | K11: =DATEDIF(G11,I11,"Y") -> 21 | L11: =DATEDIF(G11,$H$2,"Y") -> 33 | M11: =IF($N$2-J11<=0,0,($N$2-J11)) -> 0 | N11: =ROUND(H11*(1+$K$2)^(M11),0) -> 11100 | O11: =N11*VLOOKUP($K11,[1]สูตร!$A$5:$D$10,4) -> 147963 | P11: =VLOOKUP(J11,[1]สูตร!$A$14:$D$19,4) -> 1 | Q11: =+O11*P11 -> 147963 | R11: =IF(J11>=$F$3,Q11,ROUND(Q11*L11/K11,2)) -> 147963
A12: 8 | C12: นางสาว | D12: วันทอง | E12: เหง้าน้อย | F12: 217747 | G12: 238650 | H12: 13800 | I12: =DATE(YEAR(F12)+$N$2,MONTH(F12),DAY(F12)) -> 239661 | J12: =DATEDIF(F12,$H$2,"Y") -> 71 | K12: =DATEDIF(G12,I12,"Y") -> 2 | L12: =DATEDIF(G12,$H$2,"Y") -> 14 | M12: =IF($N$2-J12<=0,0,($N$2-J12)) -> 0 | N12: =ROUND(H12*(1+$K$2)^(M12),0) -> 13800 | O12: =N12*VLOOKUP($K12,[1]สูตร!$A$5:$D$10,4) -> 41400 | P12: =VLOOKUP(J12,[1]สูตร!$A$14:$D$19,4) -> 1 | Q12: =+O12*P12 -> 41400 | R12: =IF(J12>=$F$3,Q12,ROUND(Q12*L12/K12,2)) -> 41400
A13: 9 | C13: นางสาว | D13: ปรัศนียา | E13: ทุสินแก่น | F13: 218092 | G13: 239251 | H13: 10590 | I13: =DATE(YEAR(F13)+$N$2,MONTH(F13),DAY(F13)) -> 240006 | J13: =DATEDIF(F13,$H$2,"Y") -> 70 | K13: =DATEDIF(G13,I13,"Y") -> 2 | L13: =DATEDIF(G13,$H$2,"Y") -> 12 | M13: =IF($N$2-J13<=0,0,($N$2-J13)) -> 0 | N13: =ROUND(H13*(1+$K$2)^(M13),0) -> 10590 | O13: =N13*VLOOKUP($K13,[1]สูตร!$A$5:$D$10,4) -> 31770 | P13: =VLOOKUP(J13,[1]สูตร!$A$14:$D$19,4) -> 1 | Q13: =+O13*P13 -> 31770 | R13: =IF(J13>=$F$3,Q13,ROUND(Q13*L13/K13,2)) -> 31770
A14: 10 | C14: นางสาว | D14: ชลอ | E14: พูลเตี้ย | F14: 218607 | G14: 235765 | H14: 0 | I14: =DATE(YEAR(F14)+$N$2,MONTH(F14),DAY(F14)) -> 240521 | J14: =DATEDIF(F14,$H$2,"Y") -> 69 | K14: =DATEDIF(G14,I14,"Y") -> 13 | L14: =DATEDIF(G14,$H$2,"Y") -> 22 | M14: =IF($N$2-J14<=0,0,($N$2-J14)) -> 0 | N14: =ROUND(H14*(1+$K$2)^(M14),0) -> 0 | O14: =N14*VLOOKUP($K14,[1]สูตร!$A$5:$D$10,4) -> 0 | P14: =VLOOKUP(J14,[1]สูตร!$A$14:$D$19,4) -> 1 | Q14: =+O14*P14 -> 0 | R14: =IF(J14>=$F$3,Q14,ROUND(Q14*L14/K14,2)) -> 0
A15: 11 | C15: นาย | D15: สายยนต์ | E15: บุญมี | F15: 219273 | G15: 232664 | H15: 10590 | I15: =DATE(YEAR(F15)+$N$2,MONTH(F15),DAY(F15)) -> 241188 | J15: =DATEDIF(F15,$H$2,"Y") -> 67 | K15: =DATEDIF(G15,I15,"Y") -> 23 | L15: =DATEDIF(G15,$H$2,"Y") -> 30 | M15: =IF($N$2-J15<=0,0,($N$2-J15)) -> 0 | N15: =ROUND(H15*(1+$K$2)^(M15),0) -> 10590 | O15: =N15*VLOOKUP($K15,[1]สูตร!$A$5:$D$10,4) -> 141164.7 | P15: =VLOOKUP(J15,[1]สูตร!$A$14:$D$19,4) -> 1 | Q15: =+O15*P15 -> 141164.7 | R15: =IF(J15>=$F$3,Q15,ROUND(Q15*L15/K15,2)) -> 141164.7
A16: 12 | C16: นาย | D16: ธนชาต | E16: เดชากาญจนาพร | F16: 219395 | G16: 230470 | H16: 61000 | I16: =DATE(YEAR(F16)+$N$2,MONTH(F16),DAY(F16)) -> 241310 | J16: =DATEDIF(F16,$H$2,"Y") -> 67 | K16: =DATEDIF(G16,I16,"Y") -> 29 | L16: =DATEDIF(G16,$H$2,"Y") -> 36 | M16: =IF($N$2-J16<=0,0,($N$2-J16)) -> 0 | N16: =ROUND(H16*(1+$K$2)^(M16),0) -> 61000 | O16: =N16*VLOOKUP($K16,[1]สูตร!$A$5:$D$10,4) -> 813130 | P16: =VLOOKUP(J16,[1]สูตร!$A$14:$D$19,4) -> 1 | Q16: =+O16*P16 -> 813130 | R16: =IF(J16>=$F$3,Q16,ROUND(Q16*L16/K16,2)) -> 813130
A17: 13 | C17: นางสาว | D17: จิ๋ม | E17: สังข์ทอง | F17: 219459 | G17: 237011 | H17: 10590 | I17: =DATE(YEAR(F17)+$N$2,MONTH(F17),DAY(F17)) -> 241374 | J17: =DATEDIF(F17,$H$2,"Y") -> 67 | K17: =DATEDIF(G17,I17,"Y") -> 11 | L17: =DATEDIF(G17,$H$2,"Y") -> 19 | M17: =IF($N$2-J17<=0,0,($N$2-J17)) -> 0 | N17: =ROUND(H17*(1+$K$2)^(M17),0) -> 10590 | O17: =N17*VLOOKUP($K17,[1]สูตร!$A$5:$D$10,4) -> 105900 | P17: =VLOOKUP(J17,[1]สูตร!$A$14:$D$19,4) -> 1 | Q17: =+O17*P17 -> 105900 | R17: =IF(J17>=$F$3,Q17,ROUND(Q17*L17/K17,2)) -> 105900
A18: 14 | C18: นางสาว | D18: น้อย | E18: แสนโชติ | F18: 219179 | G18: 240722 | I18: =DATE(YEAR(F18)+$N$2,MONTH(F18),DAY(F18)) -> 241093 | J18: =DATEDIF(F18,$H$2,"Y") -> 67 | K18: =DATEDIF(G18,I18,"Y") -> 1 | L18: =DATEDIF(G18,$H$2,"Y") -> 8 | M18: =IF($N$2-J18<=0,0,($N$2-J18)) -> 0 | N18: =ROUND(H18*(1+$K$2)^(M18),0) -> 0 | O18: =N18*VLOOKUP($K18,[1]สูตร!$A$5:$D$10,4) -> 0 | P18: =VLOOKUP(J18,[1]สูตร!$A$14:$D$19,4) -> 1 | Q18: =+O18*P18 -> 0 | R18: =IF(J18>=$F$3,Q18,ROUND(Q18*L18/K18,2)) -> 0
A19: 15 | C19: นาง | D19: ปภังกร | E19: เดชากาญจนาพร | F19: 219607 | G19: 230470 | H19: 28800 | I19: =DATE(YEAR(F19)+$N$2,MONTH(F19),DAY(F19)) -> 241522 | J19: =DATEDIF(F19,$H$2,"Y") -> 66 | K19: =DATEDIF(G19,I19,"Y") -> 30 | L19: =DATEDIF(G19,$H$2,"Y") -> 36 | M19: =IF($N$2-J19<=0,0,($N$2-J19)) -> 0 | N19: =ROUND(H19*(1+$K$2)^(M19),0) -> 28800 | O19: =N19*VLOOKUP($K19,[1]สูตร!$A$5:$D$10,4) -> 383904 | P19: =VLOOKUP(J19,[1]สูตร!$A$14:$D$19,4) -> 1 | Q19: =+O19*P19 -> 383904 | R19: =IF(J19>=$F$3,Q19,ROUND(Q19*L19/K19,2)) -> 383904
A20: 16 | C20: นาง | D20: เพลินพิศ | E20: แก้วเปี่ยม | F20: 219861 | G20: 231201 | H20: 48500 | I20: =DATE(YEAR(F20)+$N$2,MONTH(F20),DAY(F20)) -> 241776 | J20: =DATEDIF(F20,$H$2,"Y") -> 66 | K20: =DATEDIF(G20,I20,"Y") -> 28 | L20: =DATEDIF(G20,$H$2,"Y") -> 34 | M20: =IF($N$2-J20<=0,0,($N$2-J20)) -> 0 | N20: =ROUND(H20*(1+$K$2)^(M20),0) -> 48500 | O20: =N20*VLOOKUP($K20,[1]สูตร!$A$5:$D$10,4) -> 646505 | P20: =VLOOKUP(J20,[1]สูตร!$A$14:$D$19,4) -> 1 | Q20: =+O20*P20 -> 646505 | R20: =IF(J20>=$F$3,Q20,ROUND(Q20*L20/K20,2)) -> 646505
A21: 17 | C21: นาย | D21: ชอบ | E21: ทองเกร็จ | F21: 219859 | G21: 238707 | H21: 16500 | I21: =DATE(YEAR(F21)+$N$2,MONTH(F21),DAY(F21)) -> 241774 | J21: =DATEDIF(F21,$H$2,"Y") -> 66 | K21: =DATEDIF(G21,I21,"Y") -> 8 | L21: =DATEDIF(G21,$H$2,"Y") -> 14 | M21: =IF($N$2-J21<=0,0,($N$2-J21)) -> 0 | N21: =ROUND(H21*(1+$K$2)^(M21),0) -> 16500 | O21: =N21*VLOOKUP($K21,[1]สูตร!$A$5:$D$10,4) -> 132000 | P21: =VLOOKUP(J21,[1]สูตร!$A$14:$D$19,4) -> 1 | Q21: =+O21*P21 -> 132000 | R21: =IF(J21>=$F$3,Q21,ROUND(Q21*L21/K21,2)) -> 132000
A22: 18 | C22: นาง | D22: ทองดาว | E22: ทาทิวัน | F22: 220040 | G22: 235187 | H22: 0 | I22: =DATE(YEAR(F22)+$N$2,MONTH(F22),DAY(F22)) -> 241955 | J22: =DATEDIF(F22,$H$2,"Y") -> 65 | K22: =DATEDIF(G22,I22,"Y") -> 18 | L22: =DATEDIF(G22,$H$2,"Y") -> 24 | M22: =IF($N$2-J22<=0,0,($N$2-J22)) -> 0 | N22: =ROUND(H22*(1+$K$2)^(M22),0) -> 0 | O22: =N22*VLOOKUP($K22,[1]สูตร!$A$5:$D$10,4) -> 0 | P22: =VLOOKUP(J22,[1]สูตร!$A$14:$D$19,4) -> 1 | Q22: =+O22*P22 -> 0 | R22: =IF(J22>=$F$3,Q22,ROUND(Q22*L22/K22,2)) -> 0
A23: 19 | C23: นาย | D23: พล | E23: โถทอง | F23: 220037 | G23: 230590 | H23: 21390 | I23: =DATE(YEAR(F23)+$N$2,MONTH(F23),DAY(F23)) -> 241952 | J23: =DATEDIF(F23,$H$2,"Y") -> 65 | K23: =DATEDIF(G23,I23,"Y") -> 31 | L23: =DATEDIF(G23,$H$2,"Y") -> 36 | M23: =IF($N$2-J23<=0,0,($N$2-J23)) -> 0 | N23: =ROUND(H23*(1+$K$2)^(M23),0) -> 21390 | O23: =N23*VLOOKUP($K23,[1]สูตร!$A$5:$D$10,4) -> 285128.7 | P23: =VLOOKUP(J23,[1]สูตร!$A$14:$D$19,4) -> 1 | Q23: =+O23*P23 -> 285128.7 | R23: =IF(J23>=$F$3,Q23,ROUND(Q23*L23/K23,2)) -> 285128.7
A24: 20 | C24: นาย | D24: ประสิทธิ์ | E24: อยู่จุ้ย | F24: 219887 | G24: 232777 | H24: 10590 | I24: =DATE(YEAR(F24)+$N$2,MONTH(F24),DAY(F24)) -> 241802 | J24: =DATEDIF(F24,$H$2,"Y") -> 65 | K24: =DATEDIF(G24,I24,"Y") -> 24 | L24: =DATEDIF(G24,$H$2,"Y") -> 30 | M24: =IF($N$2-J24<=0,0,($N$2-J24)) -> 0 | N24: =ROUND(H24*(1+$K$2)^(M24),0) -> 10590 | O24: =N24*VLOOKUP($K24,[1]สูตร!$A$5:$D$10,4) -> 141164.7 | P24: =VLOOKUP(J24,[1]สูตร!$A$14:$D$19,4) -> 1 | Q24: =+O24*P24 -> 141164.7 | R24: =IF(J24>=$F$3,Q24,ROUND(Q24*L24/K24,2)) -> 141164.7
A25: 21 | C25: นาง | D25: ปลอด | E25: พงษ์สังข์ | F25: 220229 | G25: 237228 | H25: 11130 | I25: =DATE(YEAR(F25)+$N$2,MONTH(F25),DAY(F25)) -> 242144 | J25: =DATEDIF(F25,$H$2,"Y") -> 65 | K25: =DATEDIF(G25,I25,"Y") -> 13 | L25: =DATEDIF(G25,$H$2,"Y") -> 18 | M25: =IF($N$2-J25<=0,0,($N$2-J25)) -> 0 | N25: =ROUND(H25*(1+$K$2)^(M25),0) -> 11130 | O25: =N25*VLOOKUP($K25,[1]สูตร!$A$5:$D$10,4) -> 111300 | P25: =VLOOKUP(J25,[1]สูตร!$A$14:$D$19,4) -> 1 | Q25: =+O25*P25 -> 111300 | R25: =IF(J25>=$F$3,Q25,ROUND(Q25*L25/K25,2)) -> 111300
A26: 22 | C26: นาง | D26: หวาน | E26: แท่งทอง | F26: 220248 | G26: 233501 | H26: 10590 | I26: =DATE(YEAR(F26)+$N$2,MONTH(F26),DAY(F26)) -> 242163 | J26: =DATEDIF(F26,$H$2,"Y") -> 64 | K26: =DATEDIF(G26,I26,"Y") -> 23 | L26: =DATEDIF(G26,$H$2,"Y") -> 28 | M26: =IF($N$2-J26<=0,0,($N$2-J26)) -> 0 | N26: =ROUND(H26*(1+$K$2)^(M26),0) -> 10590 | O26: =N26*VLOOKUP($K26,[1]สูตร!$A$5:$D$10,4) -> 141164.7 | P26: =VLOOKUP(J26,[1]สูตร!$A$14:$D$19,4) -> 1 | Q26: =+O26*P26 -> 141164.7 | R26: =IF(J26>=$F$3,Q26,ROUND(Q26*L26/K26,2)) -> 141164.7
A27: 23 | C27: นาย | D27: บุญทา | E27: ธรรมขันทา | F27: 220346 | G27: 233553 | H27: 14700 | I27: =DATE(YEAR(F27)+$N$2,MONTH(F27),DAY(F27)) -> 242261 | J27: =DATEDIF(F27,$H$2,"Y") -> 64 | K27: =DATEDIF(G27,I27,"Y") -> 23 | L27: =DATEDIF(G27,$H$2,"Y") -> 28 | M27: =IF($N$2-J27<=0,0,($N$2-J27)) -> 0 | N27: =ROUND(H27*(1+$K$2)^(M27),0) -> 14700 | O27: =N27*VLOOKUP($K27,[1]สูตร!$A$5:$D$10,4) -> 195951 | P27: =VLOOKUP(J27,[1]สูตร!$A$14:$D$19,4) -> 1 | Q27: =+O27*P27 -> 195951 | R27: =IF(J27>=$F$3,Q27,ROUND(Q27*L27/K27,2)) -> 195951
A28: 24 | C28: นาย | D28: ประไพ | E28: ศิริ | F28: 220373 | G28: 231778 | H28: 10590 | I28: =DATE(YEAR(F28)+$N$2,MONTH(F28),DAY(F28)) -> 242288 | J28: =DATEDIF(F28,$H$2,"Y") -> 64 | K28: =DATEDIF(G28,I28,"Y") -> 28 | L28: =DATEDIF(G28,$H$2,"Y") -> 33 | M28: =IF($N$2-J28<=0,0,($N$2-J28)) -> 0 | N28: =ROUND(H28*(1+$K$2)^(M28),0) -> 10590 | O28: =N28*VLOOKUP($K28,[1]สูตร!$A$5:$D$10,4) -> 141164.7 | P28: =VLOOKUP(J28,[1]สูตร!$A$14:$D$19,4) -> 1 | Q28: =+O28*P28 -> 141164.7 | R28: =IF(J28>=$F$3,Q28,ROUND(Q28*L28/K28,2)) -> 141164.7
A29: 25 | C29: นาง | D29: สงวน | E29: ปรีชาญาดีกุล | F29: 220475 | G29: 234374 | H29: 0 | I29: =DATE(YEAR(F29)+$N$2,MONTH(F29),DAY(F29)) -> 242390 | J29: =DATEDIF(F29,$H$2,"Y") -> 64 | K29: =DATEDIF(G29,I29,"Y") -> 21 | L29: =DATEDIF(G29,$H$2,"Y") -> 26 | M29: =IF($N$2-J29<=0,0,($N$2-J29)) -> 0 | N29: =ROUND(H29*(1+$K$2)^(M29),0) -> 0 | O29: =N29*VLOOKUP($K29,[1]สูตร!$A$5:$D$10,4) -> 0 | P29: =VLOOKUP(J29,[1]สูตร!$A$14:$D$19,4) -> 1 | Q29: =+O29*P29 -> 0 | R29: =IF(J29>=$F$3,Q29,ROUND(Q29*L29/K29,2)) -> 0
A30: 26 | C30: นางสาว | D30: ทองสุข | E30: แสนโชติ | F30: 220480 | G30: 231778 | H30: 15750 | I30: =DATE(YEAR(F30)+$N$2,MONTH(F30),DAY(F30)) -> 242395 | J30: =DATEDIF(F30,$H$2,"Y") -> 64 | K30: =DATEDIF(G30,I30,"Y") -> 29 | L30: =DATEDIF(G30,$H$2,"Y") -> 33 | M30: =IF($N$2-J30<=0,0,($N$2-J30)) -> 0 | N30: =ROUND(H30*(1+$K$2)^(M30),0) -> 15750 | O30: =N30*VLOOKUP($K30,[1]สูตร!$A$5:$D$10,4) -> 209947.5 | P30: =VLOOKUP(J30,[1]สูตร!$A$14:$D$19,4) -> 1 | Q30: =+O30*P30 -> 209947.5 | R30: =IF(J30>=$F$3,Q30,ROUND(Q30*L30/K30,2)) -> 209947.5
... A109: 105 | C109: นาย | D109: ณรงค์ชัย | E109: โพธิสระ | F109: 227997 | G109: 239762 | H109: 11100 | I109: =DATE(YEAR(F109)+$N$2,MONTH(F109),DAY(F109)) -> 249912 | J109: =DATEDIF(F109,$H$2,"Y") -> 43 | K109: =DATEDIF(G109,I109,"Y") -> 27 | L109: =DATEDIF(G109,$H$2,"Y") -> 11 | M109: =IF($N$2-J109<=0,0,($N$2-J109)) -> 17 | N109: =ROUND(H109*(1+$K$2)^(M109),0) -> 18347 | O109: =N109*VLOOKUP($K109,[1]สูตร!$A$5:$D$10,4) -> 244565.51 | P109: =VLOOKUP(J109,[1]สูตร!$A$14:$D$19,4) -> 0.5 | Q109: =+O109*P109 -> 122282.76 | R109: =IF(J109>=$F$3,Q109,ROUND(Q109*L109/K109,2)) -> 122282.76
A110: 106 | C110: นางสาว | D110: ปทิดา | E110: เลิศศิริมาลัย | F110: 228090 | G110: 240575 | I110: =DATE(YEAR(F110)+$N$2,MONTH(F110),DAY(F110)) -> 250005 | J110: =DATEDIF(F110,$H$2,"Y") -> 43 | K110: =DATEDIF(G110,I110,"Y") -> 25 | L110: =DATEDIF(G110,$H$2,"Y") -> 9 | M110: =IF($N$2-J110<=0,0,($N$2-J110)) -> 17 | N110: =ROUND(H110*(1+$K$2)^(M110),0) -> 0 | O110: =N110*VLOOKUP($K110,[1]สูตร!$A$5:$D$10,4) -> 0 | P110: =VLOOKUP(J110,[1]สูตร!$A$14:$D$19,4) -> 0.5 | Q110: =+O110*P110 -> 0 | R110: =IF(J110>=$F$3,Q110,ROUND(Q110*L110/K110,2)) -> 0
A111: 107 | C111: นาย | D111: เทพพร | E111: โพธิวัฒน์ | F111: 228129 | G111: 237965 | H111: 10860 | I111: =DATE(YEAR(F111)+$N$2,MONTH(F111),DAY(F111)) -> 250044 | J111: =DATEDIF(F111,$H$2,"Y") -> 43 | K111: =DATEDIF(G111,I111,"Y") -> 33 | L111: =DATEDIF(G111,$H$2,"Y") -> 16 | M111: =IF($N$2-J111<=0,0,($N$2-J111)) -> 17 | N111: =ROUND(H111*(1+$K$2)^(M111),0) -> 17950 | O111: =N111*VLOOKUP($K111,[1]สูตร!$A$5:$D$10,4) -> 239273.5 | P111: =VLOOKUP(J111,[1]สูตร!$A$14:$D$19,4) -> 0.5 | Q111: =+O111*P111 -> 119636.75 | R111: =IF(J111>=$F$3,Q111,ROUND(Q111*L111/K111,2)) -> 119636.75
A112: 108 | C112: นางสาว | D112: สุภวรรณ | E112: หัวรักกิจ | F112: 228164 | G112: 238123 | H112: 28100 | I112: =DATE(YEAR(F112)+$N$2,MONTH(F112),DAY(F112)) -> 250079 | J112: =DATEDIF(F112,$H$2,"Y") -> 43 | K112: =DATEDIF(G112,I112,"Y") -> 32 | L112: =DATEDIF(G112,$H$2,"Y") -> 16 | M112: =IF($N$2-J112<=0,0,($N$2-J112)) -> 17 | N112: =ROUND(H112*(1+$K$2)^(M112),0) -> 46445 | O112: =N112*VLOOKUP($K112,[1]สูตร!$A$5:$D$10,4) -> 619111.85 | P112: =VLOOKUP(J112,[1]สูตร!$A$14:$D$19,4) -> 0.5 | Q112: =+O112*P112 -> 309555.92 | R112: =IF(J112>=$F$3,Q112,ROUND(Q112*L112/K112,2)) -> 309555.92
A113: 109 | C113: นาย | D113: สาทิตย์ | E113: ปั้นขอม | F113: 228273 | G113: 235087 | H113: 12600 | I113: =DATE(YEAR(F113)+$N$2,MONTH(F113),DAY(F113)) -> 250188 | J113: =DATEDIF(F113,$H$2,"Y") -> 43 | K113: =DATEDIF(G113,I113,"Y") -> 41 | L113: =DATEDIF(G113,$H$2,"Y") -> 24 | M113: =IF($N$2-J113<=0,0,($N$2-J113)) -> 17 | N113: =ROUND(H113*(1+$K$2)^(M113),0) -> 20826 | O113: =N113*VLOOKUP($K113,[1]สูตร!$A$5:$D$10,4) -> 277610.58 | P113: =VLOOKUP(J113,[1]สูตร!$A$14:$D$19,4) -> 0.5 | Q113: =+O113*P113 -> 138805.29 | R113: =IF(J113>=$F$3,Q113,ROUND(Q113*L113/K113,2)) -> 138805.29
A114: 110 | C114: นางสาว | D114: อ้อยทิพย์ | E114: คำภาจันทร์ | F114: 228451 | G114: 237852 | H114: 10590 | I114: =DATE(YEAR(F114)+$N$2,MONTH(F114),DAY(F114)) -> 250366 | J114: =DATEDIF(F114,$H$2,"Y") -> 42 | K114: =DATEDIF(G114,I114,"Y") -> 34 | L114: =DATEDIF(G114,$H$2,"Y") -> 16 | M114: =IF($N$2-J114<=0,0,($N$2-J114)) -> 18 | N114: =ROUND(H114*(1+$K$2)^(M114),0) -> 18029 | O114: =N114*VLOOKUP($K114,[1]สูตร!$A$5:$D$10,4) -> 240326.57 | P114: =VLOOKUP(J114,[1]สูตร!$A$14:$D$19,4) -> 0.5 | Q114: =+O114*P114 -> 120163.29 | R114: =IF(J114>=$F$3,Q114,ROUND(Q114*L114/K114,2)) -> 120163.29
A115: 111 | C115: นาย | D115: รัฐภูมิ | E115: แปงใจ | F115: 228511 | G115: 241648 | H115: 10590 | I115: =DATE(YEAR(F115)+$N$2,MONTH(F115),DAY(F115)) -> 250426 | J115: =DATEDIF(F115,$H$2,"Y") -> 42 | K115: =DATEDIF(G115,I115,"Y") -> 24 | L115: =DATEDIF(G115,$H$2,"Y") -> 6 | M115: =IF($N$2-J115<=0,0,($N$2-J115)) -> 18 | N115: =ROUND(H115*(1+$K$2)^(M115),0) -> 18029 | O115: =N115*VLOOKUP($K115,[1]สูตร!$A$5:$D$10,4) -> 240326.57 | P115: =VLOOKUP(J115,[1]สูตร!$A$14:$D$19,4) -> 0.5 | Q115: =+O115*P115 -> 120163.29 | R115: =IF(J115>=$F$3,Q115,ROUND(Q115*L115/K115,2)) -> 120163.29
A116: 112 | C116: นาย | D116: อนันท์ | E116: โถทอง | F116: 228562 | G116: 238006 | H116: 11850 | I116: =DATE(YEAR(F116)+$N$2,MONTH(F116),DAY(F116)) -> 250477 | J116: =DATEDIF(F116,$H$2,"Y") -> 42 | K116: =DATEDIF(G116,I116,"Y") -> 34 | L116: =DATEDIF(G116,$H$2,"Y") -> 16 | M116: =IF($N$2-J116<=0,0,($N$2-J116)) -> 18 | N116: =ROUND(H116*(1+$K$2)^(M116),0) -> 20174 | O116: =N116*VLOOKUP($K116,[1]สูตร!$A$5:$D$10,4) -> 268919.42 | P116: =VLOOKUP(J116,[1]สูตร!$A$14:$D$19,4) -> 0.5 | Q116: =+O116*P116 -> 134459.71 | R116: =IF(J116>=$F$3,Q116,ROUND(Q116*L116/K116,2)) -> 134459.71
A117: 113 | C117: นางสาว | D117: ฐิติกาญจน์ | E117: ดีเจริญ | F117: 228615 | G117: 240010 | H117: 0 | I117: =DATE(YEAR(F117)+$N$2,MONTH(F117),DAY(F117)) -> 250530 | J117: =DATEDIF(F117,$H$2,"Y") -> 42 | K117: =DATEDIF(G117,I117,"Y") -> 28 | L117: =DATEDIF(G117,$H$2,"Y") -> 10 | M117: =IF($N$2-J117<=0,0,($N$2-J117)) -> 18 | N117: =ROUND(H117*(1+$K$2)^(M117),0) -> 0 | O117: =N117*VLOOKUP($K117,[1]สูตร!$A$5:$D$10,4) -> 0 | P117: =VLOOKUP(J117,[1]สูตร!$A$14:$D$19,4) -> 0.5 | Q117: =+O117*P117 -> 0 | R117: =IF(J117>=$F$3,Q117,ROUND(Q117*L117/K117,2)) -> 0
A118: 114 | C118: นางสาว | D118: สมพิศ | E118: มุ่งต่อ | F118: 228778 | G118: 239974 | H118: 10590 | I118: =DATE(YEAR(F118)+$N$2,MONTH(F118),DAY(F118)) -> 250693 | J118: =DATEDIF(F118,$H$2,"Y") -> 41 | K118: =DATEDIF(G118,I118,"Y") -> 29 | L118: =DATEDIF(G118,$H$2,"Y") -> 10 | M118: =IF($N$2-J118<=0,0,($N$2-J118)) -> 19 | N118: =ROUND(H118*(1+$K$2)^(M118),0) -> 18570 | O118: =N118*VLOOKUP($K118,[1]สูตร!$A$5:$D$10,4) -> 247538.1 | P118: =VLOOKUP(J118,[1]สูตร!$A$14:$D$19,4) -> 0.5 | Q118: =+O118*P118 -> 123769.05 | R118: =IF(J118>=$F$3,Q118,ROUND(Q118*L118/K118,2)) -> 123769.05
...

Sheet สูตร
A1: ผลประโยชน์ที่ต้องจ่ายตาม พ.ร.บ. คุ้มครองแรงงาน (ม.118)
A2: ระยะเวลาการทำงาน | D2: เงินชดเชยฯ
A3: ช่วงอายุงาน | C3: อายุ | D3: (เดือน)
A4: 0 | B4: 0.33 | C4: ไม่ถึง 120 วัน | D4: 0
A5: 0.33 | B5: 1 | C5: 120 วัน แต่ไม่ถึง 1 ปี | D5: 1
A6: =B5+1 -> 2 | B6: 2 | C6: 1 ปี แต่ไม่ถึง 3 ปี | D6: 3
A7: =B6+1 -> 3 | B7: 5 | C7: 3 ปี แต่ไม่ถึง 6 ปี | D7: 6
A8: =B7+1 -> 6 | B8: 9 | C8: 6 ปี แต่ไม่ถึง 10 ปี | D8: 8
A9: =B8+1 -> 10 | B9: 19 | C9: 10 ปี แต่ไม่ถึง 20ปี | D9: 10
A10: 20 | C10: 20 ปีขึ้นไป | D10: 13.33
A12: % ความน่าจะเป็นที่บริษัทจะต้องจ่ายผลประโยชน์พนักงาน
A13: ช่วงอายุต่ำ | B13: ช่วงอายุสูง | C13: อายุ | D13: ความน่าจะเป็น
A14: 1 | B14: 30 | C14: น้อยกว่าหรือเท่ากับ 30 | D14: 0
A15: 31 | B15: 40 | C15: 31-40 | D15: 0.2
A16: 41 | B16: 45 | C16: 41-45 | D16: 0.5
A17: 46 | B17: 50 | C17: 46-50 | D17: 0.6
A18: 51 | B18: 55 | C18: 51-55 | D18: 0.9
A19: 55 | B19: 60 | C19: 55-60 | D19: 1
